INFO:werkzeug: * Running on http://0.0.0.0:3111/ (Press CTRL+C to quit)
DEBUG:root:2021-08-19 23:58:07.394875, Article "CNCF Cloud Native Definition v1.0" retrived
INFO:werkzeug:127.0.0.1 - - [19/Aug/2021 23:58:07] "GET /5 HTTP/1.1" 200 -
INFO:werkzeug:127.0.0.1 - - [19/Aug/2021 23:58:10] "GET / HTTP/1.1" 200 -
DEBUG:root:2021-08-19 23:58:16.465200, Article "2020 CNCF Annual Report" retrived
INFO:werkzeug:127.0.0.1 - - [19/Aug/2021 23:58:16] "GET /1 HTTP/1.1" 200 -
INFO:werkzeug:127.0.0.1 - - [19/Aug/2021 23:58:18] "GET / HTTP/1.1" 200 -
INFO:app:Metrics request successfull
DEBUG:root:2021-08-19 23:58:33.705133,/metrics endpoint was reached.
INFO:werkzeug:127.0.0.1 - - [19/Aug/2021 23:58:33] "GET /metrics HTTP/1.1" 200 -
INFO:werkzeug: * Running on http://0.0.0.0:3111/ (Press CTRL+C to quit)
ERROR:app:Exception on / [GET]
Traceback (most recent call last):
  File "F:\Users\Madai\anaconda3\envs\Udacity\lib\site-packages\flask\app.py", line 2446, in wsgi_app
    response = self.full_dispatch_request()
  File "F:\Users\Madai\anaconda3\envs\Udacity\lib\site-packages\flask\app.py", line 1951, in full_dispatch_request
    rv = self.handle_user_exception(e)
  File "F:\Users\Madai\anaconda3\envs\Udacity\lib\site-packages\flask\app.py", line 1820, in handle_user_exception
    reraise(exc_type, exc_value, tb)
  File "F:\Users\Madai\anaconda3\envs\Udacity\lib\site-packages\flask\_compat.py", line 39, in reraise
    raise value
  File "F:\Users\Madai\anaconda3\envs\Udacity\lib\site-packages\flask\app.py", line 1949, in full_dispatch_request
    rv = self.dispatch_request()
  File "F:\Users\Madai\anaconda3\envs\Udacity\lib\site-packages\flask\app.py", line 1935, in dispatch_request
    return self.view_functions[rule.endpoint](**req.view_args)
  File "G:\SoftwareProjects\UdacityNanoDegrees\Suse Cloud Native\Projects\1. TechTrends\nd064_course_1\project\techtrends\app.py", line 38, in index
    connection = get_db_connection()
  File "G:\SoftwareProjects\UdacityNanoDegrees\Suse Cloud Native\Projects\1. TechTrends\nd064_course_1\project\techtrends\app.py", line 21, in get_db_connection
    db_connection_count += 1
UnboundLocalError: local variable 'db_connection_count' referenced before assignment
INFO:werkzeug:127.0.0.1 - - [19/Aug/2021 23:58:57] "GET / HTTP/1.1" 500 -
INFO:app:Metrics request successfull
DEBUG:root:2021-08-19 23:58:59.412493,/metrics endpoint was reached.
INFO:werkzeug:127.0.0.1 - - [19/Aug/2021 23:58:59] "GET /metrics HTTP/1.1" 200 -
INFO:app:Metrics request successfull
DEBUG:root:2021-08-19 23:59:00.378002,/metrics endpoint was reached.
INFO:werkzeug:127.0.0.1 - - [19/Aug/2021 23:59:00] "GET /metrics HTTP/1.1" 200 -
